Workbook
Name _____xlnm.Print_Area_4: #REF!
Name _____xlnm.Print_Area_5: #REF!
Name ____xlnm.Print_Area_1: #REF!
Name ____xlnm.Print_Area_4: #REF!
Name ____xlnm.Print_Area_5: #REF!
Name ___xlnm.Print_Area_1: #REF!
Name ___xlnm.Print_Area_4: #REF!
Name ___xlnm.Print_Area_5: #REF!
Name __xlnm.Print_Area_1: #REF!
Name __xlnm.Print_Area_4: #REF!
Name __xlnm.Print_Area_5: #REF!
Name meisai: #N/A
Name rypou: #REF!
Name エリア: #REF!
Name エリア１: #REF!
Name エリア2: #REF!
Name エリア４: #REF!
Name サイズ: #REF!
Name 運賃: #REF!
Name 運賃２: #REF!
Name 運賃３: #REF!
Name 運賃４: #REF!
Name 運賃５: #REF!
Name 個数: #REF!
Name 広電向け運賃請求書: #REF!
Name 住所Ｍ: #REF!
Name 重量: #REF!
Name 重量１: #REF!
Name 商品リスト: #REF!
Name 商品リスト1: #REF!
Name 商品リスト3: #REF!
Name 条件: #REF!
Name 条件３: #REF!
Name 条件４: #REF!
Name 条件５: #REF!
Name 適応: #REF!
Name 都道府県: #REF!
Name 入力ホーム: #REF!
Name 保護領域: #REF!,#REF!,#REF!,#REF!,#REF!,#REF!,#REF!,#REF!,#REF!,#REF!,#REF!,#REF!,#REF!,#REF!,#REF!,#REF!
Name 保護領域１: #REF!,#REF!,#REF!,#REF!,#REF!,#REF!,#REF!,#REF!,#REF!,#REF!,#REF!,#REF!,#REF!
Name 保護領域２: #REF!,#REF!,#REF!,#REF!,#REF!,#REF!
Name 保護領域S2の1: #REF!,#REF!,#REF!,#REF!,#REF!,#REF!,#REF!,#REF!,#REF!,#REF!,#REF!,#REF!,#REF!,#REF!,#REF!,#REF!,#REF!,#REF!,#REF!,#REF!,#REF!,#REF!,#REF!,#REF!,#REF!
Name 料金: #REF!
Name 料金１: #REF!
Name 料金２: #REF!

Sheet 請求書表
I1: 作成日 | J1: 46112
B2: 請求書 (正) | I2: 請求書番号 | J2: =RIGHT(CELL("FILENAME",J2),12) -> te.xlsx]請求書表
I5: 株式会社ビジネスラボ
H7: 〒103-0026
H8: 東京都中央区日本橋兜町17番2号 兜町第6葉山ビル4階
H9: TEL: 03-6555-4496 FAX: 03-4496-4103
B10: 経理ご担当者様 | H10: 登録番号：T7010003027314
B12: いつもご利用いただき、誠にありがとうございます。下記の通りご請求申し上げます。
B13: 合計
B14: =SUM(H28:H53)+SUM(G17:H18) -> 49961
B17: 10%対象 | C17: =SUMIF(I28:I53,"10%課税",H28:H53) -> 27237 | E17: 10%消費税 | G17: =ROUND(C17*0.1,0) -> 2724
B18: 8%対象 | C18: =SUMIF(I28:I53,"8%課税",H28:H53) -> 0 | E18: 8%消費税 | G18: =ROUND(C18*0.8,0) -> 0
B20: 作業名 | C20: 海上輸入 | G20: INVOICE NO.
B21: 積地 | G21: 個数
B22: 仕向地 | G22: 重量
B23: 便名 | G23: 容積
B24: ETA | G24: 備考 | H24: 2月3日AM横浜市神奈川区納品
B25: BL NO. | H25: 429
B27: 日付 | C27: 項目 | E27: 数量 | G27: 単価 | H27: 総額 | I27: 税区分 | J27: 備考
B28: 46052 | C28: 輸入通関料 | E28: 2 | F28: 葉 | G28: 10000 | H28: =IF(C28="","",IF(I28="課税",ROUND(E28*G28*1.1,0),ROUND(E28*G28,0))) -> 20000 | I28: 非課税 | J28: 3欄＝2葉
B29: =B28 -> 46052 | C29: 取扱料 | E29: 1 | F29: 件 | G29: 7000 | H29: =IF(C29="","",IF(I29="課税",ROUND(E29*G29*1.1,0),ROUND(E29*G29,0))) -> 7000 | I29: 10%課税
B30: 46056 | C30: コンテナドレージ | E30: 0.413 | F30: 40HQ | G30: 49000 | H30: =IF(C30="","",IF(I30="課税",ROUND(E30*G30*1.1,0),ROUND(E30*G30,0))) -> 20237 | I30: 10%課税
B31: =C24 -> 0 | H31: =IF(C31="","",IF(I31="課税",ROUND(E31*G31*1.1,0),ROUND(E31*G31*J31,0)))
B32: =B31 -> 0 | H32: =IF(C32="","",IF(I32="課税",ROUND(E32*G32*1.1,0),ROUND(E32*G32,0)))
B33: =B32 -> 0 | H33: =IF(C33="","",IF(I33="課税",ROUND(E33*G33*1.1,0),ROUND(E33*G33,0)))
B34: =B33 -> 0 | H34: =IF(C34="","",IF(I34="課税",ROUND(E34*G34*1.1,0),ROUND(E34*G34,0)))
B35: =B34 -> 0 | H35: =IF(C35="","",IF(I35="課税",ROUND(E35*G35*1.1,0),ROUND(E35*G35,0)))
B36: =B35 -> 0 | H36: =IF(C36="","",IF(I36="課税",ROUND(E36*G36*1.1,0),ROUND(E36*G36*J36,0)))
B37: =B36 -> 0 | H37: =IF(C37="","",IF(I37="課税",ROUND(E37*G37*1.1,0),ROUND(E37*G37,0)))
B38: =B37 -> 0 | H38: =IF(C38="","",IF(I38="課税",ROUND(E38*G38*1.1,0),ROUND(E38*G38,0)))
H47: =IF(B47="","",ROUND(E47*G47,0))
H48: =IF(B48="","",ROUND(E48*G48,0))
H49: =IF(B49="","",ROUND(E49*G49,0))
H50: =IF(B50="","",ROUND(E50*G50,0))
H51: =IF(B51="","",ROUND(E51*G51,0))
H52: =IF(B52="","",ROUND(E52*G52,0))
B54: お支払いは、 | C54: =EOMONTH(J1,1) -> 46142 | E54: までに、下記銀行口座までお振込下さいますよう、お願い申し上げます。
B55: また誠に恐れ入りますが、振込手数料はご負担頂きます様、お願い申し上げます。
B56: 取引銀行 | C56: 三井住友銀行 日本橋東支店 普通 7828377 ｶ)ﾋﾞｼﾞﾈｽﾗﾎﾞ

Sheet 請求書裏
B1: 税区分 | C1: 売上 | D1: 仕入 | G1: 科目 | H1: 正誤判定
B2: 課税(消費税抜) | C2: =F24 -> 32237 | D2: =J24 -> 50500 | G2: 合計金額 | H2: =IF(請求書表!B14=SUM(請求書裏!C2:C6),"〇","チェックが必要") -> チェックが必要
B3: 課税(消費税額) | C3: =G24 -> 3224 | D3: =K24 -> 5050
B4: 非課税 | C4: =F39 -> 20000 | D4: =J39 -> 68400 | G4: 課税 | H4: 消費税 | I4: 非課税 | J4: 対象外 | K4: 立替 | L4: 請求合計 | M4: 下払い合計
B5: 対象外 | C5: =F54 -> 0 | D5: =J54 -> 0 | E5: 粗利 | G5: =C2 -> 32237 | H5: =C3 -> 3224 | I5: =C4 -> 20000 | J5: =C5 -> 0 | K5: =C6 -> 0 | L5: =SUM(C2:C6) -> 55461 | M5: =D2+D4+D5 -> 118900
B6: 立替金 | C6: =F69 -> 0 | D6: =J69 -> 0 | E6: =SUM(C2+C4+C5+C6)-SUM(D2+D4+D5+D6) -> -66663
B7: 売上 | H7: 仕入
B8: 請求項目 | C8: 数量 | D8: 請求単価 | F8: 請求金額 | G8: 税額 | H8: 数量 | I8: 仕入単価 | J8: 仕入金額 | K8: 税額 | L8: 仕入先 | M8: 請求書番号 | N8: 支払期日
B9: 課税項目 | H9: 課税項目
B10: 取扱料 | C10: 1 | D10: 7000 | F10: =IF(D10="","",ROUND(C10*D10,0)) -> 7000 | G10: =IF(F10="","",ROUND(F10*0.1,0)) -> 700 | H10: =IF(C10="", "", C10) -> 1 | I10: 3000 | J10: =IF(I10="","",ROUND(H10*I10,0)) -> 3000 | K10: =IF(J10="","",ROUND(J10*0.1,0)) -> 300 | L10: 天行株式会社 | M10: TM002313 | N10: 46081
B11: コンテナドレージ | C11: 1 | D11: =請求書表!H30 -> 20237 | F11: =IF(D11="","",ROUND(C11*D11,0)) -> 20237 | G11: =IF(F11="","",ROUND(F11*0.1,0)) -> 2024 | H11: =IF(C11="", "", C11) -> 1 | I11: 43000 | J11: =IF(I11="","",ROUND(H11*I11,0)) -> 43000 | K11: =IF(J11="","",ROUND(J11*0.1,0)) -> 4300 | L11: 東方国際物流株式会社 | M11: 2/3 | N11: 46112
B12: D/O FEE | C12: 1 | D12: 5000 | F12: =IF(D12="","",ROUND(C12*D12,0)) -> 5000 | G12: =IF(F12="","",ROUND(F12*0.1,0)) -> 500 | H12: =IF(C12="", "", C12) -> 1 | J12: =IF(I12="","",ROUND(H12*I12,0)) | K12: =IF(J12="","",ROUND(J12*0.1,0))
B13: BL FEE | C13: 1 | D13: =請求書表!H33 | F13: =IF(D13="","",ROUND(C13*D13,0)) | G13: =IF(F13="","",ROUND(F13*0.1,0)) | H13: =IF(C13="", "", C13) -> 1 | I13: 4500 | J13: =IF(I13="","",ROUND(H13*I13,0)) -> 4500 | K13: =IF(J13="","",ROUND(J13*0.1,0)) -> 450 | L13: 天行株式会社 | M13: TM002313 | N13: 46081
F14: =IF(D14="","",ROUND(C14*D14,0)) | G14: =IF(F14="","",ROUND(F14*0.1,0)) | H14: =IF(C14="", "", C14) | J14: =IF(I14="","",ROUND(H14*I14,0)) | K14: =IF(J14="","",ROUND(J14*0.1,0))
F15: =IF(D15="","",ROUND(C15*D15,0)) | G15: =IF(F15="","",ROUND(F15*0.1,0)) | H15: =IF(C15="", "", C15) | J15: =IF(I15="","",ROUND(H15*I15,0)) | K15: =IF(J15="","",ROUND(J15*0.1,0))
F16: =IF(D16="","",ROUND(C16*D16,0)) | G16: =IF(F16="","",ROUND(F16*0.1,0)) | H16: =IF(C16="", "", C16) | J16: =IF(I16="","",ROUND(H16*I16,0)) | K16: =IF(J16="","",ROUND(J16*0.1,0))
F17: =IF(D17="","",ROUND(C17*D17,0)) | G17: =IF(F17="","",ROUND(F17*0.1,0)) | H17: =IF(C17="", "", C17) | J17: =IF(I17="","",ROUND(H17*I17,0)) | K17: =IF(J17="","",ROUND(J17*0.1,0))
F18: =IF(D18="","",ROUND(C18*D18,0)) | G18: =IF(F18="","",ROUND(F18*0.1,0)) | H18: =IF(C18="", "", C18) | J18: =IF(I18="","",ROUND(H18*I18,0)) | K18: =IF(J18="","",ROUND(J18*0.1,0))
F19: =IF(D19="","",ROUND(C19*D19,0)) | G19: =IF(F19="","",ROUND(F19*0.1,0)) | H19: =IF(C19="", "", C19) | J19: =IF(I19="","",ROUND(H19*I19,0)) | K19: =IF(J19="","",ROUND(J19*0.1,0))
F20: =IF(D20="","",ROUND(C20*D20,0)) | G20: =IF(F20="","",ROUND(F20*0.1,0)) | H20: =IF(C20="", "", C20) | J20: =IF(I20="","",ROUND(H20*I20,0)) | K20: =IF(J20="","",ROUND(J20*0.1,0))
F21: =IF(D21="","",ROUND(C21*D21,0)) | G21: =IF(F21="","",ROUND(F21*0.1,0)) | H21: =IF(C21="", "", C21) | J21: =IF(I21="","",ROUND(H21*I21,0)) | K21: =IF(J21="","",ROUND(J21*0.1,0))
F22: =IF(D22="","",ROUND(C22*D22,0)) | G22: =IF(F22="","",ROUND(F22*0.1,0)) | H22: =IF(C22="", "", C22) | J22: =IF(I22="","",ROUND(H22*I22,0)) | K22: =IF(J22="","",ROUND(J22*0.1,0))
F23: =IF(D23="","",ROUND(C23*D23,0)) | G23: =IF(F23="","",ROUND(F23*0.1,0)) | H23: =IF(C23="", "", C23) | J23: =IF(I23="","",ROUND(H23*I23,0)) | K23: =IF(J23="","",ROUND(J23*0.1,0))
E24: 合計 | F24: =SUM(F10:F23) -> 32237 | G24: =IF(F24="","",ROUND(F24*0.1,0)) -> 3224 | H24: =IF(C24="", "", C24) | I24: 合計 | J24: =SUM(J10:J23) -> 50500 | K24: =IF(J24="","",ROUND(J24*0.1,0)) -> 5050
B25: 非課税項目 | C25: 数量 | D25: 請求単価 | F25: 請求金額 | H25: 非課税項目 | I25: 仕入単価 | J25: 仕入金額 | L25: 仕入先 | M25: 請求書番号 | N25: 支払期日
B26: 輸入通関料 | C26: =請求書表!E28 -> 2 | D26: 10000 | F26: =IF(D26="","",ROUND(C26*D26,0)) -> 20000 | H26: =IF(C26="", "", C26) -> 2 | I26: 8000 | J26: =IF(I26="","",ROUND(H26*I26,0)) -> 16000 | L26: 天行株式会社 | M26: TM002313 | N26: 46081
B27: THC | C27: 1 | D27: =請求書表!H32 | F27: =IF(D27="","",ROUND(C27*D27,0)) | H27: =IF(C27="", "", C27) -> 1 | I27: 52900 | J27: =IF(I27="","",ROUND(H27*I27,0)) -> 52900 | L27: 天行株式会社 | M27: TM002313 | N27: 46081
B28: CIC | C28: 1 | D28: =請求書表!H35 | F28: =IF(D28="","",ROUND(C28*D28,0)) | H28: =IF(C28="", "", C28) -> 1 | I28: 4600 | J28: =IF(I28="","",ROUND(H28*I28,0)) -> 4600 | L28: 天行株式会社 | M28: TM002313 | N28: 46081
B29: EQUIPMENT MANAGE | C29: 1 | D29: =請求書表!H37 | F29: =IF(D29="","",ROUND(C29*D29,0)) | H29: =IF(C29="", "", C29) -> 1 | I29: 1300 | J29: =IF(I29="","",ROUND(H29*I29,0)) -> 1300 | L29: 天行株式会社 | M29: TM002313 | N29: 46081
B30: CONGESTION SURCHARGE | C30: 1 | D30: =請求書表!H38 | F30: =IF(D30="","",ROUND(C30*D30,0)) | H30: =IF(C30="", "", C30) -> 1 | I30: 1600 | J30: =IF(I30="","",ROUND(H30*I30,0)) -> 1600 | L30: 天行株式会社 | M30: TM002313 | N30: 46081
B31: 差額 | C31: 1 | F31: =IF(D31="","",ROUND(C31*D31,0)) | H31: =IF(C31="", "", C31) -> 1 | I31: -8000 | J31: =IF(I31="","",ROUND(H31*I31,0)) -> -8000 | L31: 天行株式会社 | M31: TM002313 | N31: 46081
F32: =IF(D32="","",ROUND(C32*D32,0)) | H32: =IF(C32="", "", C32) | J32: =IF(I32="","",ROUND(H32*I32,0))
F33: =IF(D33="","",ROUND(C33*D33,0)) | H33: =IF(C33="", "", C33) | J33: =IF(I33="","",ROUND(H33*I33,0))
F34: =IF(D34="","",ROUND(C34*D34,0)) | H34: =IF(C34="", "", C34) | J34: =IF(I34="","",ROUND(H34*I34,0))
F35: =IF(D35="","",ROUND(C35*D35,0)) | H35: =IF(C35="", "", C35) | J35: =IF(I35="","",ROUND(H35*I35,0))
F36: =IF(D36="","",ROUND(C36*D36,0)) | H36: =IF(C36="", "", C36) | J36: =IF(I36="","",ROUND(H36*I36,0))
F37: =IF(D37="","",ROUND(C37*D37,0)) | H37: =IF(C37="", "", C37) | J37: =IF(I37="","",ROUND(H37*I37,0))
F38: =IF(D38="","",ROUND(C38*D38,0)) | H38: =IF(C38="", "", C38) | J38: =IF(I38="","",ROUND(H38*I38,0))
E39: 合計 | F39: =SUM(F25:F38) -> 20000 | H39: =IF(C39="", "", C39) | I39: 合計 | J39: =SUM(J25:J38) -> 68400
B40: 対象外項目 | C40: 数量 | D40: 請求単価 | F40: 請求金額 | H40: 対象外項目 | I40: 仕入単価 | J40: 仕入金額 | L40: 仕入先 | M40: 請求書番号 | N40: 支払期日
...
